[2022-08-23 03:08:58,129] {taskinstance.py:1032} INFO - Dependencies all met for <TaskInstance: h1b_lca_data.download_data_task scheduled__2022-04-10T06:00:00+00:00 [queued]>
[2022-08-23 03:08:58,183] {taskinstance.py:1032} INFO - Dependencies all met for <TaskInstance: h1b_lca_data.download_data_task scheduled__2022-04-10T06:00:00+00:00 [queued]>
[2022-08-23 03:08:58,185] {taskinstance.py:1238} INFO - 
--------------------------------------------------------------------------------
[2022-08-23 03:08:58,186] {taskinstance.py:1239} INFO - Starting attempt 1 of 1
[2022-08-23 03:08:58,187] {taskinstance.py:1240} INFO - 
--------------------------------------------------------------------------------
[2022-08-23 03:08:58,214] {taskinstance.py:1259} INFO - Executing <Task(BashOperator): download_data_task> on 2022-04-10 06:00:00+00:00
[2022-08-23 03:08:58,238] {standard_task_runner.py:52} INFO - Started process 286 to run task
[2022-08-23 03:08:58,242] {standard_task_runner.py:76} INFO - Running: ['***', 'tasks', 'run', 'h1b_lca_data', 'download_data_task', 'scheduled__2022-04-10T06:00:00+00:00', '--job-id', '200', '--raw', '--subdir', 'DAGS_FOLDER/upload_h1b_data_to_gcp.py', '--cfg-path', '/tmp/tmpr9j2gywo', '--error-file', '/tmp/tmp4c5nzzxv']
[2022-08-23 03:08:58,247] {standard_task_runner.py:77} INFO - Job 200: Subtask download_data_task
[2022-08-23 03:08:58,367] {logging_mixin.py:109} INFO - Running <TaskInstance: h1b_lca_data.download_data_task scheduled__2022-04-10T06:00:00+00:00 [running]> on host 0afddbd69de7
[2022-08-23 03:08:58,460] {warnings.py:110} WARNING - /home/***/.local/lib/python3.7/site-packages/***/utils/context.py:152: AirflowContextDeprecationWarning: Accessing 'execution_date' from the template is deprecated and will be removed in a future version. Please use 'data_interval_start' or 'logical_date' instead.
  warnings.warn(_create_deprecation_warning(key, self._deprecation_replacements[key]))

[2022-08-23 03:08:58,772] {taskinstance.py:1426} INFO - Exporting the following env vars:
AIRFLOW_CTX_DAG_OWNER=***
AIRFLOW_CTX_DAG_ID=h1b_lca_data
AIRFLOW_CTX_TASK_ID=download_data_task
AIRFLOW_CTX_EXECUTION_DATE=2022-04-10T06:00:00+00:00
AIRFLOW_CTX_DAG_RUN_ID=scheduled__2022-04-10T06:00:00+00:00
[2022-08-23 03:08:58,776] {subprocess.py:62} INFO - Tmp dir root location: 
 /tmp
[2022-08-23 03:08:58,779] {subprocess.py:74} INFO - Running command: ['bash', '-c', "curl -sSL https://www.dol.gov/sites/dolgov/files/ETA/oflc/pdfs/LCA_Disclosure_Data_FY2022{ execution_date.strftime('%q') }}.xlsx > /opt/***/LCA_Disclosure_Data_FY"]
[2022-08-23 03:08:58,801] {subprocess.py:85} INFO - Output:
[2022-08-23 03:08:58,819] {subprocess.py:89} INFO - bash: -c: line 0: syntax error near unexpected token `('
[2022-08-23 03:08:58,823] {subprocess.py:89} INFO - bash: -c: line 0: `curl -sSL https://www.dol.gov/sites/dolgov/files/ETA/oflc/pdfs/LCA_Disclosure_Data_FY2022{ execution_date.strftime('%q') }}.xlsx > /opt/***/LCA_Disclosure_Data_FY'
[2022-08-23 03:08:58,827] {subprocess.py:93} INFO - Command exited with return code 1
[2022-08-23 03:08:59,054] {taskinstance.py:1700} ERROR - Task failed with exception
Traceback (most recent call last):
  File "/home/airflow/.local/lib/python3.7/site-packages/airflow/models/taskinstance.py", line 1329, in _run_raw_task
    self._execute_task_with_callbacks(context)
  File "/home/airflow/.local/lib/python3.7/site-packages/airflow/models/taskinstance.py", line 1455, in _execute_task_with_callbacks
    result = self._execute_task(context, self.task)
  File "/home/airflow/.local/lib/python3.7/site-packages/airflow/models/taskinstance.py", line 1511, in _execute_task
    result = execute_callable(context=context)
  File "/home/airflow/.local/lib/python3.7/site-packages/airflow/operators/bash.py", line 188, in execute
    f'Bash command failed. The command returned a non-zero exit code {result.exit_code}.'
airflow.exceptions.AirflowException: Bash command failed. The command returned a non-zero exit code 1.
[2022-08-23 03:08:59,073] {taskinstance.py:1277} INFO - Marking task as FAILED. dag_id=h1b_lca_data, task_id=download_data_task, execution_date=20220410T060000, start_date=20220823T030858, end_date=20220823T030859
[2022-08-23 03:08:59,147] {standard_task_runner.py:92} ERROR - Failed to execute job 200 for task download_data_task
Traceback (most recent call last):
  File "/home/airflow/.local/lib/python3.7/site-packages/airflow/task/task_runner/standard_task_runner.py", line 85, in _start_by_fork
    args.func(args, dag=self.dag)
  File "/home/airflow/.local/lib/python3.7/site-packages/airflow/cli/cli_parser.py", line 48, in command
    return func(*args, **kwargs)
  File "/home/airflow/.local/lib/python3.7/site-packages/airflow/utils/cli.py", line 92, in wrapper
    return f(*args, **kwargs)
  File "/home/airflow/.local/lib/python3.7/site-packages/airflow/cli/commands/task_command.py", line 298, in task_run
    _run_task_by_selected_method(args, dag, ti)
  File "/home/airflow/.local/lib/python3.7/site-packages/airflow/cli/commands/task_command.py", line 107, in _run_task_by_selected_method
    _run_raw_task(args, ti)
  File "/home/airflow/.local/lib/python3.7/site-packages/airflow/cli/commands/task_command.py", line 184, in _run_raw_task
    error_file=args.error_file,
  File "/home/airflow/.local/lib/python3.7/site-packages/airflow/utils/session.py", line 70, in wrapper
    return func(*args, session=session, **kwargs)
  File "/home/airflow/.local/lib/python3.7/site-packages/airflow/models/taskinstance.py", line 1329, in _run_raw_task
    self._execute_task_with_callbacks(context)
  File "/home/airflow/.local/lib/python3.7/site-packages/airflow/models/taskinstance.py", line 1455, in _execute_task_with_callbacks
    result = self._execute_task(context, self.task)
  File "/home/airflow/.local/lib/python3.7/site-packages/airflow/models/taskinstance.py", line 1511, in _execute_task
    result = execute_callable(context=context)
  File "/home/airflow/.local/lib/python3.7/site-packages/airflow/operators/bash.py", line 188, in execute
    f'Bash command failed. The command returned a non-zero exit code {result.exit_code}.'
airflow.exceptions.AirflowException: Bash command failed. The command returned a non-zero exit code 1.
[2022-08-23 03:08:59,211] {local_task_job.py:154} INFO - Task exited with return code 1
[2022-08-23 03:08:59,262] {local_task_job.py:264} INFO - 0 downstream tasks scheduled from follow-on schedule check
