[2022-08-29 16:01:19,188] {taskinstance.py:1032} INFO - Dependencies all met for <TaskInstance: h1b_lca_data_v3.entry_task scheduled__2021-01-10T06:00:00+00:00 [queued]>
[2022-08-29 16:01:19,203] {taskinstance.py:1032} INFO - Dependencies all met for <TaskInstance: h1b_lca_data_v3.entry_task scheduled__2021-01-10T06:00:00+00:00 [queued]>
[2022-08-29 16:01:19,204] {taskinstance.py:1238} INFO - 
--------------------------------------------------------------------------------
[2022-08-29 16:01:19,205] {taskinstance.py:1239} INFO - Starting attempt 35 of 35
[2022-08-29 16:01:19,207] {taskinstance.py:1240} INFO - 
--------------------------------------------------------------------------------
[2022-08-29 16:01:19,226] {taskinstance.py:1259} INFO - Executing <Task(BashOperator): entry_task> on 2021-01-10 06:00:00+00:00
[2022-08-29 16:01:19,234] {standard_task_runner.py:52} INFO - Started process 12766 to run task
[2022-08-29 16:01:19,238] {standard_task_runner.py:76} INFO - Running: ['***', 'tasks', 'run', 'h1b_lca_data_v3', 'entry_task', 'scheduled__2021-01-10T06:00:00+00:00', '--job-id', '1553', '--raw', '--subdir', 'DAGS_FOLDER/upload_h1b_data_to_gcp.py', '--cfg-path', '/tmp/tmpdbihvq7j', '--error-file', '/tmp/tmp_hpotsxc']
[2022-08-29 16:01:19,240] {standard_task_runner.py:77} INFO - Job 1553: Subtask entry_task
[2022-08-29 16:01:19,317] {logging_mixin.py:109} INFO - Running <TaskInstance: h1b_lca_data_v3.entry_task scheduled__2021-01-10T06:00:00+00:00 [running]> on host efb24f1b01c6
[2022-08-29 16:01:19,392] {taskinstance.py:1426} INFO - Exporting the following env vars:
AIRFLOW_CTX_DAG_OWNER=***
AIRFLOW_CTX_DAG_ID=h1b_lca_data_v3
AIRFLOW_CTX_TASK_ID=entry_task
AIRFLOW_CTX_EXECUTION_DATE=2021-01-10T06:00:00+00:00
AIRFLOW_CTX_DAG_RUN_ID=scheduled__2021-01-10T06:00:00+00:00
[2022-08-29 16:01:19,395] {subprocess.py:62} INFO - Tmp dir root location: 
 /tmp
[2022-08-29 16:01:19,397] {subprocess.py:74} INFO - Running command: ['bash', '-c', 'echo 1|int']
[2022-08-29 16:01:19,415] {subprocess.py:85} INFO - Output:
[2022-08-29 16:01:19,419] {subprocess.py:89} INFO - bash: int: command not found
[2022-08-29 16:01:19,421] {subprocess.py:93} INFO - Command exited with return code 127
[2022-08-29 16:01:19,442] {taskinstance.py:1700} ERROR - Task failed with exception
Traceback (most recent call last):
  File "/home/airflow/.local/lib/python3.7/site-packages/airflow/models/taskinstance.py", line 1329, in _run_raw_task
    self._execute_task_with_callbacks(context)
  File "/home/airflow/.local/lib/python3.7/site-packages/airflow/models/taskinstance.py", line 1455, in _execute_task_with_callbacks
    result = self._execute_task(context, self.task)
  File "/home/airflow/.local/lib/python3.7/site-packages/airflow/models/taskinstance.py", line 1511, in _execute_task
    result = execute_callable(context=context)
  File "/home/airflow/.local/lib/python3.7/site-packages/airflow/operators/bash.py", line 188, in execute
    f'Bash command failed. The command returned a non-zero exit code {result.exit_code}.'
airflow.exceptions.AirflowException: Bash command failed. The command returned a non-zero exit code 127.
[2022-08-29 16:01:19,453] {taskinstance.py:1277} INFO - Marking task as FAILED. dag_id=h1b_lca_data_v3, task_id=entry_task, execution_date=20210110T060000, start_date=20220829T160119, end_date=20220829T160119
[2022-08-29 16:01:19,475] {standard_task_runner.py:92} ERROR - Failed to execute job 1553 for task entry_task
Traceback (most recent call last):
  File "/home/airflow/.local/lib/python3.7/site-packages/airflow/task/task_runner/standard_task_runner.py", line 85, in _start_by_fork
    args.func(args, dag=self.dag)
  File "/home/airflow/.local/lib/python3.7/site-packages/airflow/cli/cli_parser.py", line 48, in command
    return func(*args, **kwargs)
  File "/home/airflow/.local/lib/python3.7/site-packages/airflow/utils/cli.py", line 92, in wrapper
    return f(*args, **kwargs)
  File "/home/airflow/.local/lib/python3.7/site-packages/airflow/cli/commands/task_command.py", line 298, in task_run
    _run_task_by_selected_method(args, dag, ti)
  File "/home/airflow/.local/lib/python3.7/site-packages/airflow/cli/commands/task_command.py", line 107, in _run_task_by_selected_method
    _run_raw_task(args, ti)
  File "/home/airflow/.local/lib/python3.7/site-packages/airflow/cli/commands/task_command.py", line 184, in _run_raw_task
    error_file=args.error_file,
  File "/home/airflow/.local/lib/python3.7/site-packages/airflow/utils/session.py", line 70, in wrapper
    return func(*args, session=session, **kwargs)
  File "/home/airflow/.local/lib/python3.7/site-packages/airflow/models/taskinstance.py", line 1329, in _run_raw_task
    self._execute_task_with_callbacks(context)
  File "/home/airflow/.local/lib/python3.7/site-packages/airflow/models/taskinstance.py", line 1455, in _execute_task_with_callbacks
    result = self._execute_task(context, self.task)
  File "/home/airflow/.local/lib/python3.7/site-packages/airflow/models/taskinstance.py", line 1511, in _execute_task
    result = execute_callable(context=context)
  File "/home/airflow/.local/lib/python3.7/site-packages/airflow/operators/bash.py", line 188, in execute
    f'Bash command failed. The command returned a non-zero exit code {result.exit_code}.'
airflow.exceptions.AirflowException: Bash command failed. The command returned a non-zero exit code 127.
[2022-08-29 16:01:19,537] {local_task_job.py:154} INFO - Task exited with return code 1
[2022-08-29 16:01:19,580] {local_task_job.py:264} INFO - 0 downstream tasks scheduled from follow-on schedule check
