[2022-08-29 16:03:31,270] {taskinstance.py:1032} INFO - Dependencies all met for <TaskInstance: h1b_lca_data_v3.entry_task scheduled__2021-01-10T06:00:00+00:00 [queued]>
[2022-08-29 16:03:31,286] {taskinstance.py:1032} INFO - Dependencies all met for <TaskInstance: h1b_lca_data_v3.entry_task scheduled__2021-01-10T06:00:00+00:00 [queued]>
[2022-08-29 16:03:31,287] {taskinstance.py:1238} INFO - 
--------------------------------------------------------------------------------
[2022-08-29 16:03:31,289] {taskinstance.py:1239} INFO - Starting attempt 38 of 38
[2022-08-29 16:03:31,290] {taskinstance.py:1240} INFO - 
--------------------------------------------------------------------------------
[2022-08-29 16:03:31,310] {taskinstance.py:1259} INFO - Executing <Task(BashOperator): entry_task> on 2021-01-10 06:00:00+00:00
[2022-08-29 16:03:31,319] {standard_task_runner.py:52} INFO - Started process 12878 to run task
[2022-08-29 16:03:31,324] {standard_task_runner.py:76} INFO - Running: ['***', 'tasks', 'run', 'h1b_lca_data_v3', 'entry_task', 'scheduled__2021-01-10T06:00:00+00:00', '--job-id', '1556', '--raw', '--subdir', 'DAGS_FOLDER/upload_h1b_data_to_gcp.py', '--cfg-path', '/tmp/tmpq0h7310y', '--error-file', '/tmp/tmpbfuw_3j2']
[2022-08-29 16:03:31,326] {standard_task_runner.py:77} INFO - Job 1556: Subtask entry_task
[2022-08-29 16:03:31,401] {logging_mixin.py:109} INFO - Running <TaskInstance: h1b_lca_data_v3.entry_task scheduled__2021-01-10T06:00:00+00:00 [running]> on host efb24f1b01c6
[2022-08-29 16:03:31,443] {taskinstance.py:1700} ERROR - Task failed with exception
Traceback (most recent call last):
  File "/home/airflow/.local/lib/python3.7/site-packages/airflow/models/taskinstance.py", line 1329, in _run_raw_task
    self._execute_task_with_callbacks(context)
  File "/home/airflow/.local/lib/python3.7/site-packages/airflow/models/taskinstance.py", line 1418, in _execute_task_with_callbacks
    self.render_templates(context=context)
  File "/home/airflow/.local/lib/python3.7/site-packages/airflow/models/taskinstance.py", line 1992, in render_templates
    self.task.render_template_fields(context)
  File "/home/airflow/.local/lib/python3.7/site-packages/airflow/models/baseoperator.py", line 1061, in render_template_fields
    self._do_render_template_fields(self, self.template_fields, context, jinja_env, set())
  File "/home/airflow/.local/lib/python3.7/site-packages/airflow/models/baseoperator.py", line 1074, in _do_render_template_fields
    rendered_content = self.render_template(content, context, jinja_env, seen_oids)
  File "/home/airflow/.local/lib/python3.7/site-packages/airflow/models/baseoperator.py", line 1110, in render_template
    template = jinja_env.from_string(content)
  File "/home/airflow/.local/lib/python3.7/site-packages/jinja2/environment.py", line 1092, in from_string
    return cls.from_code(self, self.compile(source), gs, None)
  File "/home/airflow/.local/lib/python3.7/site-packages/jinja2/environment.py", line 757, in compile
    self.handle_exception(source=source_hint)
  File "/home/airflow/.local/lib/python3.7/site-packages/jinja2/environment.py", line 925, in handle_exception
    raise rewrite_traceback_stack(source=source)
  File "<unknown>", line 1, in template
jinja2.exceptions.TemplateSyntaxError: unexpected '%'
[2022-08-29 16:03:31,462] {taskinstance.py:1277} INFO - Marking task as FAILED. dag_id=h1b_lca_data_v3, task_id=entry_task, execution_date=20210110T060000, start_date=20220829T160331, end_date=20220829T160331
[2022-08-29 16:03:31,480] {standard_task_runner.py:92} ERROR - Failed to execute job 1556 for task entry_task
Traceback (most recent call last):
  File "/home/airflow/.local/lib/python3.7/site-packages/airflow/task/task_runner/standard_task_runner.py", line 85, in _start_by_fork
    args.func(args, dag=self.dag)
  File "/home/airflow/.local/lib/python3.7/site-packages/airflow/cli/cli_parser.py", line 48, in command
    return func(*args, **kwargs)
  File "/home/airflow/.local/lib/python3.7/site-packages/airflow/utils/cli.py", line 92, in wrapper
    return f(*args, **kwargs)
  File "/home/airflow/.local/lib/python3.7/site-packages/airflow/cli/commands/task_command.py", line 298, in task_run
    _run_task_by_selected_method(args, dag, ti)
  File "/home/airflow/.local/lib/python3.7/site-packages/airflow/cli/commands/task_command.py", line 107, in _run_task_by_selected_method
    _run_raw_task(args, ti)
  File "/home/airflow/.local/lib/python3.7/site-packages/airflow/cli/commands/task_command.py", line 184, in _run_raw_task
    error_file=args.error_file,
  File "/home/airflow/.local/lib/python3.7/site-packages/airflow/utils/session.py", line 70, in wrapper
    return func(*args, session=session, **kwargs)
  File "/home/airflow/.local/lib/python3.7/site-packages/airflow/models/taskinstance.py", line 1329, in _run_raw_task
    self._execute_task_with_callbacks(context)
  File "/home/airflow/.local/lib/python3.7/site-packages/airflow/models/taskinstance.py", line 1418, in _execute_task_with_callbacks
    self.render_templates(context=context)
  File "/home/airflow/.local/lib/python3.7/site-packages/airflow/models/taskinstance.py", line 1992, in render_templates
    self.task.render_template_fields(context)
  File "/home/airflow/.local/lib/python3.7/site-packages/airflow/models/baseoperator.py", line 1061, in render_template_fields
    self._do_render_template_fields(self, self.template_fields, context, jinja_env, set())
  File "/home/airflow/.local/lib/python3.7/site-packages/airflow/models/baseoperator.py", line 1074, in _do_render_template_fields
    rendered_content = self.render_template(content, context, jinja_env, seen_oids)
  File "/home/airflow/.local/lib/python3.7/site-packages/airflow/models/baseoperator.py", line 1110, in render_template
    template = jinja_env.from_string(content)
  File "/home/airflow/.local/lib/python3.7/site-packages/jinja2/environment.py", line 1092, in from_string
    return cls.from_code(self, self.compile(source), gs, None)
  File "/home/airflow/.local/lib/python3.7/site-packages/jinja2/environment.py", line 757, in compile
    self.handle_exception(source=source_hint)
  File "/home/airflow/.local/lib/python3.7/site-packages/jinja2/environment.py", line 925, in handle_exception
    raise rewrite_traceback_stack(source=source)
  File "<unknown>", line 1, in template
jinja2.exceptions.TemplateSyntaxError: unexpected '%'
[2022-08-29 16:03:31,500] {local_task_job.py:154} INFO - Task exited with return code 1
[2022-08-29 16:03:31,540] {local_task_job.py:264} INFO - 0 downstream tasks scheduled from follow-on schedule check
