[2022-08-29 16:54:49,131] {taskinstance.py:1032} INFO - Dependencies all met for <TaskInstance: h1b_lca_data_v3.entry_task scheduled__2021-04-10T06:00:00+00:00 [queued]>
[2022-08-29 16:54:49,152] {taskinstance.py:1032} INFO - Dependencies all met for <TaskInstance: h1b_lca_data_v3.entry_task scheduled__2021-04-10T06:00:00+00:00 [queued]>
[2022-08-29 16:54:49,153] {taskinstance.py:1238} INFO - 
--------------------------------------------------------------------------------
[2022-08-29 16:54:49,154] {taskinstance.py:1239} INFO - Starting attempt 48 of 48
[2022-08-29 16:54:49,155] {taskinstance.py:1240} INFO - 
--------------------------------------------------------------------------------
[2022-08-29 16:54:49,177] {taskinstance.py:1259} INFO - Executing <Task(PythonOperator): entry_task> on 2021-04-10 06:00:00+00:00
[2022-08-29 16:54:49,188] {standard_task_runner.py:52} INFO - Started process 404 to run task
[2022-08-29 16:54:49,201] {standard_task_runner.py:76} INFO - Running: ['***', 'tasks', 'run', 'h1b_lca_data_v3', 'entry_task', 'scheduled__2021-04-10T06:00:00+00:00', '--job-id', '1592', '--raw', '--subdir', 'DAGS_FOLDER/upload_h1b_data_to_gcp.py', '--cfg-path', '/tmp/tmp_0fjy7fd', '--error-file', '/tmp/tmpfve2vb_m']
[2022-08-29 16:54:49,204] {standard_task_runner.py:77} INFO - Job 1592: Subtask entry_task
[2022-08-29 16:54:49,299] {logging_mixin.py:109} INFO - Running <TaskInstance: h1b_lca_data_v3.entry_task scheduled__2021-04-10T06:00:00+00:00 [running]> on host f153c6531160
[2022-08-29 16:54:49,373] {taskinstance.py:1426} INFO - Exporting the following env vars:
AIRFLOW_CTX_DAG_OWNER=***
AIRFLOW_CTX_DAG_ID=h1b_lca_data_v3
AIRFLOW_CTX_TASK_ID=entry_task
AIRFLOW_CTX_EXECUTION_DATE=2021-04-10T06:00:00+00:00
AIRFLOW_CTX_DAG_RUN_ID=scheduled__2021-04-10T06:00:00+00:00
[2022-08-29 16:54:49,376] {taskinstance.py:1700} ERROR - Task failed with exception
Traceback (most recent call last):
  File "/home/airflow/.local/lib/python3.7/site-packages/airflow/models/taskinstance.py", line 1329, in _run_raw_task
    self._execute_task_with_callbacks(context)
  File "/home/airflow/.local/lib/python3.7/site-packages/airflow/models/taskinstance.py", line 1455, in _execute_task_with_callbacks
    result = self._execute_task(context, self.task)
  File "/home/airflow/.local/lib/python3.7/site-packages/airflow/models/taskinstance.py", line 1511, in _execute_task
    result = execute_callable(context=context)
  File "/home/airflow/.local/lib/python3.7/site-packages/airflow/operators/python.py", line 174, in execute
    return_value = self.execute_callable()
  File "/home/airflow/.local/lib/python3.7/site-packages/airflow/operators/python.py", line 185, in execute_callable
    return self.python_callable(*self.op_args, **self.op_kwargs)
  File "/opt/airflow/dags/upload_h1b_data_to_gcp.py", line 84, in test
    print(type(int(var)))
ValueError: invalid literal for int() with base 10: "{{logical_date.strftime('%-m')}}"
[2022-08-29 16:54:49,396] {taskinstance.py:1277} INFO - Marking task as FAILED. dag_id=h1b_lca_data_v3, task_id=entry_task, execution_date=20210410T060000, start_date=20220829T165449, end_date=20220829T165449
[2022-08-29 16:54:49,414] {standard_task_runner.py:92} ERROR - Failed to execute job 1592 for task entry_task
Traceback (most recent call last):
  File "/home/airflow/.local/lib/python3.7/site-packages/airflow/task/task_runner/standard_task_runner.py", line 85, in _start_by_fork
    args.func(args, dag=self.dag)
  File "/home/airflow/.local/lib/python3.7/site-packages/airflow/cli/cli_parser.py", line 48, in command
    return func(*args, **kwargs)
  File "/home/airflow/.local/lib/python3.7/site-packages/airflow/utils/cli.py", line 92, in wrapper
    return f(*args, **kwargs)
  File "/home/airflow/.local/lib/python3.7/site-packages/airflow/cli/commands/task_command.py", line 298, in task_run
    _run_task_by_selected_method(args, dag, ti)
  File "/home/airflow/.local/lib/python3.7/site-packages/airflow/cli/commands/task_command.py", line 107, in _run_task_by_selected_method
    _run_raw_task(args, ti)
  File "/home/airflow/.local/lib/python3.7/site-packages/airflow/cli/commands/task_command.py", line 184, in _run_raw_task
    error_file=args.error_file,
  File "/home/airflow/.local/lib/python3.7/site-packages/airflow/utils/session.py", line 70, in wrapper
    return func(*args, session=session, **kwargs)
  File "/home/airflow/.local/lib/python3.7/site-packages/airflow/models/taskinstance.py", line 1329, in _run_raw_task
    self._execute_task_with_callbacks(context)
  File "/home/airflow/.local/lib/python3.7/site-packages/airflow/models/taskinstance.py", line 1455, in _execute_task_with_callbacks
    result = self._execute_task(context, self.task)
  File "/home/airflow/.local/lib/python3.7/site-packages/airflow/models/taskinstance.py", line 1511, in _execute_task
    result = execute_callable(context=context)
  File "/home/airflow/.local/lib/python3.7/site-packages/airflow/operators/python.py", line 174, in execute
    return_value = self.execute_callable()
  File "/home/airflow/.local/lib/python3.7/site-packages/airflow/operators/python.py", line 185, in execute_callable
    return self.python_callable(*self.op_args, **self.op_kwargs)
  File "/opt/airflow/dags/upload_h1b_data_to_gcp.py", line 84, in test
    print(type(int(var)))
ValueError: invalid literal for int() with base 10: "{{logical_date.strftime('%-m')}}"
[2022-08-29 16:54:49,451] {local_task_job.py:154} INFO - Task exited with return code 1
[2022-08-29 16:54:49,493] {local_task_job.py:264} INFO - 0 downstream tasks scheduled from follow-on schedule check
