[2022-08-25 20:00:00,599] {taskinstance.py:1032} INFO - Dependencies all met for <TaskInstance: h1b_lca_data.format_xlsx_to_csv_task scheduled__2021-01-10T06:00:00+00:00 [queued]>
[2022-08-25 20:00:00,615] {taskinstance.py:1032} INFO - Dependencies all met for <TaskInstance: h1b_lca_data.format_xlsx_to_csv_task scheduled__2021-01-10T06:00:00+00:00 [queued]>
[2022-08-25 20:00:00,617] {taskinstance.py:1238} INFO - 
--------------------------------------------------------------------------------
[2022-08-25 20:00:00,617] {taskinstance.py:1239} INFO - Starting attempt 16 of 16
[2022-08-25 20:00:00,618] {taskinstance.py:1240} INFO - 
--------------------------------------------------------------------------------
[2022-08-25 20:00:00,635] {taskinstance.py:1259} INFO - Executing <Task(PythonOperator): format_xlsx_to_csv_task> on 2021-01-10 06:00:00+00:00
[2022-08-25 20:00:00,644] {standard_task_runner.py:52} INFO - Started process 103 to run task
[2022-08-25 20:00:00,651] {standard_task_runner.py:76} INFO - Running: ['***', 'tasks', 'run', 'h1b_lca_data', 'format_xlsx_to_csv_task', 'scheduled__2021-01-10T06:00:00+00:00', '--job-id', '312', '--raw', '--subdir', 'DAGS_FOLDER/upload_h1b_data_to_gcp.py', '--cfg-path', '/tmp/tmpm5bl5eg_', '--error-file', '/tmp/tmprxdbdsmh']
[2022-08-25 20:00:00,653] {standard_task_runner.py:77} INFO - Job 312: Subtask format_xlsx_to_csv_task
[2022-08-25 20:00:00,740] {logging_mixin.py:109} INFO - Running <TaskInstance: h1b_lca_data.format_xlsx_to_csv_task scheduled__2021-01-10T06:00:00+00:00 [running]> on host f6e4118e3ac5
[2022-08-25 20:00:00,794] {warnings.py:110} WARNING - /home/***/.local/lib/python3.7/site-packages/***/utils/context.py:152: AirflowContextDeprecationWarning: Accessing 'execution_date' from the template is deprecated and will be removed in a future version. Please use 'data_interval_start' or 'logical_date' instead.
  warnings.warn(_create_deprecation_warning(key, self._deprecation_replacements[key]))

[2022-08-25 20:00:00,819] {taskinstance.py:1426} INFO - Exporting the following env vars:
AIRFLOW_CTX_DAG_OWNER=***
AIRFLOW_CTX_DAG_ID=h1b_lca_data
AIRFLOW_CTX_TASK_ID=format_xlsx_to_csv_task
AIRFLOW_CTX_EXECUTION_DATE=2021-01-10T06:00:00+00:00
AIRFLOW_CTX_DAG_RUN_ID=scheduled__2021-01-10T06:00:00+00:00
[2022-08-25 20:00:00,821] {logging_mixin.py:109} INFO - Source file:  /opt/***/LCA_Disclosure_Data_FY2021_Q1.xlsx
[2022-08-25 20:00:00,824] {taskinstance.py:1700} ERROR - Task failed with exception
Traceback (most recent call last):
  File "/home/airflow/.local/lib/python3.7/site-packages/airflow/models/taskinstance.py", line 1329, in _run_raw_task
    self._execute_task_with_callbacks(context)
  File "/home/airflow/.local/lib/python3.7/site-packages/airflow/models/taskinstance.py", line 1455, in _execute_task_with_callbacks
    result = self._execute_task(context, self.task)
  File "/home/airflow/.local/lib/python3.7/site-packages/airflow/models/taskinstance.py", line 1511, in _execute_task
    result = execute_callable(context=context)
  File "/home/airflow/.local/lib/python3.7/site-packages/airflow/operators/python.py", line 174, in execute
    return_value = self.execute_callable()
  File "/home/airflow/.local/lib/python3.7/site-packages/airflow/operators/python.py", line 185, in execute_callable
    return self.python_callable(*self.op_args, **self.op_kwargs)
  File "/opt/airflow/dags/upload_h1b_data_to_gcp.py", line 55, in format_xlsx_to_csv
    csv_df = pd.read_excel(src_file)
  File "/home/airflow/.local/lib/python3.7/site-packages/pandas/util/_decorators.py", line 311, in wrapper
    return func(*args, **kwargs)
  File "/home/airflow/.local/lib/python3.7/site-packages/pandas/io/excel/_base.py", line 364, in read_excel
    io = ExcelFile(io, storage_options=storage_options, engine=engine)
  File "/home/airflow/.local/lib/python3.7/site-packages/pandas/io/excel/_base.py", line 1192, in __init__
    content_or_path=path_or_buffer, storage_options=storage_options
  File "/home/airflow/.local/lib/python3.7/site-packages/pandas/io/excel/_base.py", line 1071, in inspect_excel_format
    content_or_path, "rb", storage_options=storage_options, is_text=False
  File "/home/airflow/.local/lib/python3.7/site-packages/pandas/io/common.py", line 711, in get_handle
    handle = open(handle, ioargs.mode)
FileNotFoundError: [Errno 2] No such file or directory: '/opt/airflow/LCA_Disclosure_Data_FY2021_Q1.xlsx'
[2022-08-25 20:00:00,847] {taskinstance.py:1277} INFO - Marking task as FAILED. dag_id=h1b_lca_data, task_id=format_xlsx_to_csv_task, execution_date=20210110T060000, start_date=20220825T200000, end_date=20220825T200000
[2022-08-25 20:00:00,876] {standard_task_runner.py:92} ERROR - Failed to execute job 312 for task format_xlsx_to_csv_task
Traceback (most recent call last):
  File "/home/airflow/.local/lib/python3.7/site-packages/airflow/task/task_runner/standard_task_runner.py", line 85, in _start_by_fork
    args.func(args, dag=self.dag)
  File "/home/airflow/.local/lib/python3.7/site-packages/airflow/cli/cli_parser.py", line 48, in command
    return func(*args, **kwargs)
  File "/home/airflow/.local/lib/python3.7/site-packages/airflow/utils/cli.py", line 92, in wrapper
    return f(*args, **kwargs)
  File "/home/airflow/.local/lib/python3.7/site-packages/airflow/cli/commands/task_command.py", line 298, in task_run
    _run_task_by_selected_method(args, dag, ti)
  File "/home/airflow/.local/lib/python3.7/site-packages/airflow/cli/commands/task_command.py", line 107, in _run_task_by_selected_method
    _run_raw_task(args, ti)
  File "/home/airflow/.local/lib/python3.7/site-packages/airflow/cli/commands/task_command.py", line 184, in _run_raw_task
    error_file=args.error_file,
  File "/home/airflow/.local/lib/python3.7/site-packages/airflow/utils/session.py", line 70, in wrapper
    return func(*args, session=session, **kwargs)
  File "/home/airflow/.local/lib/python3.7/site-packages/airflow/models/taskinstance.py", line 1329, in _run_raw_task
    self._execute_task_with_callbacks(context)
  File "/home/airflow/.local/lib/python3.7/site-packages/airflow/models/taskinstance.py", line 1455, in _execute_task_with_callbacks
    result = self._execute_task(context, self.task)
  File "/home/airflow/.local/lib/python3.7/site-packages/airflow/models/taskinstance.py", line 1511, in _execute_task
    result = execute_callable(context=context)
  File "/home/airflow/.local/lib/python3.7/site-packages/airflow/operators/python.py", line 174, in execute
    return_value = self.execute_callable()
  File "/home/airflow/.local/lib/python3.7/site-packages/airflow/operators/python.py", line 185, in execute_callable
    return self.python_callable(*self.op_args, **self.op_kwargs)
  File "/opt/airflow/dags/upload_h1b_data_to_gcp.py", line 55, in format_xlsx_to_csv
    csv_df = pd.read_excel(src_file)
  File "/home/airflow/.local/lib/python3.7/site-packages/pandas/util/_decorators.py", line 311, in wrapper
    return func(*args, **kwargs)
  File "/home/airflow/.local/lib/python3.7/site-packages/pandas/io/excel/_base.py", line 364, in read_excel
    io = ExcelFile(io, storage_options=storage_options, engine=engine)
  File "/home/airflow/.local/lib/python3.7/site-packages/pandas/io/excel/_base.py", line 1192, in __init__
    content_or_path=path_or_buffer, storage_options=storage_options
  File "/home/airflow/.local/lib/python3.7/site-packages/pandas/io/excel/_base.py", line 1071, in inspect_excel_format
    content_or_path, "rb", storage_options=storage_options, is_text=False
  File "/home/airflow/.local/lib/python3.7/site-packages/pandas/io/common.py", line 711, in get_handle
    handle = open(handle, ioargs.mode)
FileNotFoundError: [Errno 2] No such file or directory: '/opt/airflow/LCA_Disclosure_Data_FY2021_Q1.xlsx'
[2022-08-25 20:00:00,904] {local_task_job.py:154} INFO - Task exited with return code 1
[2022-08-25 20:00:00,949] {local_task_job.py:264} INFO - 0 downstream tasks scheduled from follow-on schedule check
