[2022-08-17 14:44:28,741] {taskinstance.py:1032} INFO - Dependencies all met for <TaskInstance: bar_data_dag.format_to_parquet_task manual__2022-08-17T14:40:34.710367+00:00 [queued]>
[2022-08-17 14:44:28,759] {taskinstance.py:1032} INFO - Dependencies all met for <TaskInstance: bar_data_dag.format_to_parquet_task manual__2022-08-17T14:40:34.710367+00:00 [queued]>
[2022-08-17 14:44:28,761] {taskinstance.py:1238} INFO - 
--------------------------------------------------------------------------------
[2022-08-17 14:44:28,762] {taskinstance.py:1239} INFO - Starting attempt 3 of 3
[2022-08-17 14:44:28,763] {taskinstance.py:1240} INFO - 
--------------------------------------------------------------------------------
[2022-08-17 14:44:28,780] {taskinstance.py:1259} INFO - Executing <Task(PythonOperator): format_to_parquet_task> on 2022-08-17 14:40:34.710367+00:00
[2022-08-17 14:44:28,788] {standard_task_runner.py:52} INFO - Started process 283 to run task
[2022-08-17 14:44:28,793] {standard_task_runner.py:76} INFO - Running: ['***', 'tasks', 'run', 'bar_data_dag', 'format_to_parquet_task', 'manual__2022-08-17T14:40:34.710367+00:00', '--job-id', '145', '--raw', '--subdir', 'DAGS_FOLDER/upload_bar_data.py', '--cfg-path', '/tmp/tmpp92g6wf1', '--error-file', '/tmp/tmpaf56_3fg']
[2022-08-17 14:44:28,795] {standard_task_runner.py:77} INFO - Job 145: Subtask format_to_parquet_task
[2022-08-17 14:44:28,863] {logging_mixin.py:109} INFO - Running <TaskInstance: bar_data_dag.format_to_parquet_task manual__2022-08-17T14:40:34.710367+00:00 [running]> on host 896f1021acdc
[2022-08-17 14:44:28,922] {taskinstance.py:1426} INFO - Exporting the following env vars:
AIRFLOW_CTX_DAG_OWNER=***
AIRFLOW_CTX_DAG_ID=bar_data_dag
AIRFLOW_CTX_TASK_ID=format_to_parquet_task
AIRFLOW_CTX_EXECUTION_DATE=2022-08-17T14:40:34.710367+00:00
AIRFLOW_CTX_DAG_RUN_ID=manual__2022-08-17T14:40:34.710367+00:00
[2022-08-17 14:44:28,924] {taskinstance.py:1700} ERROR - Task failed with exception
Traceback (most recent call last):
  File "/home/airflow/.local/lib/python3.7/site-packages/airflow/models/taskinstance.py", line 1329, in _run_raw_task
    self._execute_task_with_callbacks(context)
  File "/home/airflow/.local/lib/python3.7/site-packages/airflow/models/taskinstance.py", line 1455, in _execute_task_with_callbacks
    result = self._execute_task(context, self.task)
  File "/home/airflow/.local/lib/python3.7/site-packages/airflow/models/taskinstance.py", line 1511, in _execute_task
    result = execute_callable(context=context)
  File "/home/airflow/.local/lib/python3.7/site-packages/airflow/operators/python.py", line 174, in execute
    return_value = self.execute_callable()
  File "/home/airflow/.local/lib/python3.7/site-packages/airflow/operators/python.py", line 185, in execute_callable
    return self.python_callable(*self.op_args, **self.op_kwargs)
  File "/opt/airflow/dags/upload_bar_data.py", line 38, in format_to_parquet
    table = pv.read_csv(src_file)
  File "pyarrow/_csv.pyx", line 862, in pyarrow._csv.read_csv
  File "pyarrow/_csv.pyx", line 755, in pyarrow._csv._get_reader
  File "pyarrow/io.pxi", line 1551, in pyarrow.lib.get_input_stream
  File "pyarrow/io.pxi", line 1522, in pyarrow.lib.get_native_file
  File "pyarrow/io.pxi", line 886, in pyarrow.lib.OSFile.__cinit__
  File "pyarrow/io.pxi", line 896, in pyarrow.lib.OSFile._open_readable
  File "pyarrow/error.pxi", line 143, in pyarrow.lib.pyarrow_internal_check_status
  File "pyarrow/error.pxi", line 112, in pyarrow.lib.check_status
FileNotFoundError: [Errno 2] Failed to open local file '~/Documents/Git\ Hub/personal/nyc\ bar\ crawl/data/DOHMH_New_York_City_Restaurant_Inspection_Results.csv'. Detail: [errno 2] No such file or directory
[2022-08-17 14:44:28,944] {taskinstance.py:1277} INFO - Marking task as FAILED. dag_id=bar_data_dag, task_id=format_to_parquet_task, execution_date=20220817T144034, start_date=20220817T144428, end_date=20220817T144428
[2022-08-17 14:44:28,962] {standard_task_runner.py:92} ERROR - Failed to execute job 145 for task format_to_parquet_task
Traceback (most recent call last):
  File "/home/airflow/.local/lib/python3.7/site-packages/airflow/task/task_runner/standard_task_runner.py", line 85, in _start_by_fork
    args.func(args, dag=self.dag)
  File "/home/airflow/.local/lib/python3.7/site-packages/airflow/cli/cli_parser.py", line 48, in command
    return func(*args, **kwargs)
  File "/home/airflow/.local/lib/python3.7/site-packages/airflow/utils/cli.py", line 92, in wrapper
    return f(*args, **kwargs)
  File "/home/airflow/.local/lib/python3.7/site-packages/airflow/cli/commands/task_command.py", line 298, in task_run
    _run_task_by_selected_method(args, dag, ti)
  File "/home/airflow/.local/lib/python3.7/site-packages/airflow/cli/commands/task_command.py", line 107, in _run_task_by_selected_method
    _run_raw_task(args, ti)
  File "/home/airflow/.local/lib/python3.7/site-packages/airflow/cli/commands/task_command.py", line 184, in _run_raw_task
    error_file=args.error_file,
  File "/home/airflow/.local/lib/python3.7/site-packages/airflow/utils/session.py", line 70, in wrapper
    return func(*args, session=session, **kwargs)
  File "/home/airflow/.local/lib/python3.7/site-packages/airflow/models/taskinstance.py", line 1329, in _run_raw_task
    self._execute_task_with_callbacks(context)
  File "/home/airflow/.local/lib/python3.7/site-packages/airflow/models/taskinstance.py", line 1455, in _execute_task_with_callbacks
    result = self._execute_task(context, self.task)
  File "/home/airflow/.local/lib/python3.7/site-packages/airflow/models/taskinstance.py", line 1511, in _execute_task
    result = execute_callable(context=context)
  File "/home/airflow/.local/lib/python3.7/site-packages/airflow/operators/python.py", line 174, in execute
    return_value = self.execute_callable()
  File "/home/airflow/.local/lib/python3.7/site-packages/airflow/operators/python.py", line 185, in execute_callable
    return self.python_callable(*self.op_args, **self.op_kwargs)
  File "/opt/airflow/dags/upload_bar_data.py", line 38, in format_to_parquet
    table = pv.read_csv(src_file)
  File "pyarrow/_csv.pyx", line 862, in pyarrow._csv.read_csv
  File "pyarrow/_csv.pyx", line 755, in pyarrow._csv._get_reader
  File "pyarrow/io.pxi", line 1551, in pyarrow.lib.get_input_stream
  File "pyarrow/io.pxi", line 1522, in pyarrow.lib.get_native_file
  File "pyarrow/io.pxi", line 886, in pyarrow.lib.OSFile.__cinit__
  File "pyarrow/io.pxi", line 896, in pyarrow.lib.OSFile._open_readable
  File "pyarrow/error.pxi", line 143, in pyarrow.lib.pyarrow_internal_check_status
  File "pyarrow/error.pxi", line 112, in pyarrow.lib.check_status
FileNotFoundError: [Errno 2] Failed to open local file '~/Documents/Git\ Hub/personal/nyc\ bar\ crawl/data/DOHMH_New_York_City_Restaurant_Inspection_Results.csv'. Detail: [errno 2] No such file or directory
[2022-08-17 14:44:29,010] {local_task_job.py:154} INFO - Task exited with return code 1
[2022-08-17 14:44:29,060] {local_task_job.py:264} INFO - 0 downstream tasks scheduled from follow-on schedule check
