[2022-08-23 16:06:17,067] {taskinstance.py:1032} INFO - Dependencies all met for <TaskInstance: api_dag.save_posts scheduled__2022-08-22T00:00:00+00:00 [queued]>
[2022-08-23 16:06:17,086] {taskinstance.py:1032} INFO - Dependencies all met for <TaskInstance: api_dag.save_posts scheduled__2022-08-22T00:00:00+00:00 [queued]>
[2022-08-23 16:06:17,088] {taskinstance.py:1238} INFO - 
--------------------------------------------------------------------------------
[2022-08-23 16:06:17,090] {taskinstance.py:1239} INFO - Starting attempt 4 of 4
[2022-08-23 16:06:17,091] {taskinstance.py:1240} INFO - 
--------------------------------------------------------------------------------
[2022-08-23 16:06:17,113] {taskinstance.py:1259} INFO - Executing <Task(PythonOperator): save_posts> on 2022-08-22 00:00:00+00:00
[2022-08-23 16:06:17,125] {standard_task_runner.py:52} INFO - Started process 1062 to run task
[2022-08-23 16:06:17,130] {standard_task_runner.py:76} INFO - Running: ['***', 'tasks', 'run', 'api_dag', 'save_posts', 'scheduled__2022-08-22T00:00:00+00:00', '--job-id', '264', '--raw', '--subdir', 'DAGS_FOLDER/api_dag.py', '--cfg-path', '/tmp/tmpudbzkfx7', '--error-file', '/tmp/tmpt4ej2wlo']
[2022-08-23 16:06:17,131] {standard_task_runner.py:77} INFO - Job 264: Subtask save_posts
[2022-08-23 16:06:17,203] {logging_mixin.py:109} INFO - Running <TaskInstance: api_dag.save_posts scheduled__2022-08-22T00:00:00+00:00 [running]> on host 7dedb8b41d8d
[2022-08-23 16:06:17,266] {taskinstance.py:1426} INFO - Exporting the following env vars:
AIRFLOW_CTX_DAG_OWNER=***
AIRFLOW_CTX_DAG_ID=api_dag
AIRFLOW_CTX_TASK_ID=save_posts
AIRFLOW_CTX_EXECUTION_DATE=2022-08-22T00:00:00+00:00
AIRFLOW_CTX_DAG_RUN_ID=scheduled__2022-08-22T00:00:00+00:00
[2022-08-23 16:06:17,286] {taskinstance.py:1700} ERROR - Task failed with exception
Traceback (most recent call last):
  File "/home/airflow/.local/lib/python3.7/site-packages/airflow/models/taskinstance.py", line 1329, in _run_raw_task
    self._execute_task_with_callbacks(context)
  File "/home/airflow/.local/lib/python3.7/site-packages/airflow/models/taskinstance.py", line 1455, in _execute_task_with_callbacks
    result = self._execute_task(context, self.task)
  File "/home/airflow/.local/lib/python3.7/site-packages/airflow/models/taskinstance.py", line 1511, in _execute_task
    result = execute_callable(context=context)
  File "/home/airflow/.local/lib/python3.7/site-packages/airflow/operators/python.py", line 174, in execute
    return_value = self.execute_callable()
  File "/home/airflow/.local/lib/python3.7/site-packages/airflow/operators/python.py", line 185, in execute_callable
    return self.python_callable(*self.op_args, **self.op_kwargs)
  File "/opt/airflow/dags/api_dag.py", line 10, in save_posts
    with open('./data/posts.json', 'w') as f:
FileNotFoundError: [Errno 2] No such file or directory: './data/posts.json'
[2022-08-23 16:06:17,307] {taskinstance.py:1277} INFO - Marking task as FAILED. dag_id=api_dag, task_id=save_posts, execution_date=20220822T000000, start_date=20220823T160617, end_date=20220823T160617
[2022-08-23 16:06:17,323] {standard_task_runner.py:92} ERROR - Failed to execute job 264 for task save_posts
Traceback (most recent call last):
  File "/home/airflow/.local/lib/python3.7/site-packages/airflow/task/task_runner/standard_task_runner.py", line 85, in _start_by_fork
    args.func(args, dag=self.dag)
  File "/home/airflow/.local/lib/python3.7/site-packages/airflow/cli/cli_parser.py", line 48, in command
    return func(*args, **kwargs)
  File "/home/airflow/.local/lib/python3.7/site-packages/airflow/utils/cli.py", line 92, in wrapper
    return f(*args, **kwargs)
  File "/home/airflow/.local/lib/python3.7/site-packages/airflow/cli/commands/task_command.py", line 298, in task_run
    _run_task_by_selected_method(args, dag, ti)
  File "/home/airflow/.local/lib/python3.7/site-packages/airflow/cli/commands/task_command.py", line 107, in _run_task_by_selected_method
    _run_raw_task(args, ti)
  File "/home/airflow/.local/lib/python3.7/site-packages/airflow/cli/commands/task_command.py", line 184, in _run_raw_task
    error_file=args.error_file,
  File "/home/airflow/.local/lib/python3.7/site-packages/airflow/utils/session.py", line 70, in wrapper
    return func(*args, session=session, **kwargs)
  File "/home/airflow/.local/lib/python3.7/site-packages/airflow/models/taskinstance.py", line 1329, in _run_raw_task
    self._execute_task_with_callbacks(context)
  File "/home/airflow/.local/lib/python3.7/site-packages/airflow/models/taskinstance.py", line 1455, in _execute_task_with_callbacks
    result = self._execute_task(context, self.task)
  File "/home/airflow/.local/lib/python3.7/site-packages/airflow/models/taskinstance.py", line 1511, in _execute_task
    result = execute_callable(context=context)
  File "/home/airflow/.local/lib/python3.7/site-packages/airflow/operators/python.py", line 174, in execute
    return_value = self.execute_callable()
  File "/home/airflow/.local/lib/python3.7/site-packages/airflow/operators/python.py", line 185, in execute_callable
    return self.python_callable(*self.op_args, **self.op_kwargs)
  File "/opt/airflow/dags/api_dag.py", line 10, in save_posts
    with open('./data/posts.json', 'w') as f:
FileNotFoundError: [Errno 2] No such file or directory: './data/posts.json'
[2022-08-23 16:06:17,349] {local_task_job.py:154} INFO - Task exited with return code 1
[2022-08-23 16:06:17,426] {local_task_job.py:264} INFO - 0 downstream tasks scheduled from follow-on schedule check
